<?xml version='1.0'?>
<sdf version='1.6'>
  <model name='triton'>
    <link name='lidar'>
      <inertial>
        <pose frame=''>0 0 0.161 0 -0 0</pose>
        <inertia>
          <ixx>0.001</ixx><ixy>0</ixy><ixz>0</ixz>
          <iyy>0.001</iyy><iyz>0</iyz><izz>0.001</izz>
        </inertia>
        <mass>0.125</mass>
      </inertial>
      <sensor name='hls_lfcd_lds' type='ray'>
        <always_on>1</always_on>
        <visualize>0</visualize>
        <pose frame=''>0 0 0.161 0 -0 0</pose>
        <update_rate>5</update_rate>
        <ray>
          <scan>
            <horizontal>
              <samples>360</samples><resolution>1</resolution>
              <min_angle>0</min_angle><max_angle>6.28</max_angle>
            </horizontal>
            <vertical>
              <samples>1</samples>
              <min_angle>0</min_angle><max_angle>0</max_angle>
            </vertical>
          </scan>
          <range>
            <min>0.2</min><max>10</max><resolution>0.01</resolution>
          </range>
          <noise>
            <type>gaussian</type><mean>0</mean><stddev>0.04</stddev>
          </noise>
        </ray>
        <plugin name='rplidar_a2_m12' filename='libgazebo_ros_laser.so'>
          <topicName>/__NS__/scan</topicName>
          <frameName>__NS__/base_scan</frameName>
        </plugin>
      </sensor>
      <self_collide>0</self_collide>
      <enable_wind>0</enable_wind>
      <kinematic>0</kinematic>
      <pose frame=''>0 0 0 0 -0 0</pose>
      <visual name='lidar_sensor_visual'>
        <pose frame=''>0 0 0.161 0 -0 0</pose>
        <geometry>
          <cylinder><radius>0.038</radius><length>0.041</length></cylinder>
        </geometry>
        <material>
          <ambient>0 0 0 1</ambient><diffuse>0 0 0 1</diffuse>
          <specular>0 0 0 0</specular><emissive>0 0 0 1</emissive>
        </material>
      </visual>
      <collision name='lidar_sensor_collision'>
        <pose frame=''>0 0 0.161 0 -0 0</pose>
        <geometry>
          <cylinder><radius>0.038</radius><length>0.041</length></cylinder>
        </geometry>
      </collision>
    </link>

    <link name='link_1'>
      <inertial>
        <mass>1</mass>
        <inertia>
          <ixx>0.145833</ixx><ixy>0</ixy><ixz>0</ixz>
          <iyy>0.145833</iyy><iyz>0</iyz><izz>0.125</izz>
        </inertia>
        <pose frame=''>0 0 0 0 -0 0</pose>
      </inertial>
      <pose frame=''>0 0 0.035 0 -0 0</pose>
      <gravity>1</gravity>
      <self_collide>0</self_collide>
      <kinematic>0</kinematic>
      <enable_wind>0</enable_wind>
      <visual name='visual'>
        <geometry>
          <mesh><uri>model://triton/meshes/triton.dae</uri></mesh>
        </geometry>
        <material>
          <ambient>0.5 0 0 1</ambient><diffuse>1 0 0 1</diffuse>
          <specular>0.01 0.01 0.01 1</specular><emissive>0 0 0 1</emissive>
        </material>
      </visual>
      <collision name='collision'>
        <geometry>
          <cylinder><radius>0.1</radius><length>0.004</length></cylinder>
        </geometry>
      </collision>
    </link>

    <link name='link_1_0_clone'>
      <inertial>
        <mass>1</mass>
        <inertia>
          <ixx>0.145833</ixx><ixy>0</ixy><ixz>0</ixz>
          <iyy>0.145833</iyy><iyz>0</iyz><izz>0.125</izz>
        </inertia>
      </inertial>
      <pose frame=''>0.055 0.095 0.03 2.09438 1.57 3e-06</pose>
      <gravity>1</gravity><self_collide>0</self_collide>
      <kinematic>0</kinematic><enable_wind>0</enable_wind>
      <visual name='visual_0'>
        <geometry>
          <cylinder><radius>0.03</radius><length>0.015</length></cylinder>
        </geometry>
        <material>
          <ambient>0.3 0.3 0.3 1</ambient><diffuse>0.7 0.7 0.7 1</diffuse>
          <specular>0.01 0.01 0.01 1</specular><emissive>0 0 0 1</emissive>
        </material>
        <transparency>1</transparency>
      </visual>
      <collision name='collision'>
        <geometry>
          <cylinder><radius>0.03</radius><length>0.015</length></cylinder>
        </geometry>
      </collision>
    </link>

    <link name='link_1_0_clone_clone'>
      <inertial>
        <mass>1</mass>
        <inertia>
          <ixx>0.145833</ixx><ixy>0</ixy><ixz>0</ixz>
          <iyy>0.145833</iyy><iyz>0</iyz><izz>0.125</izz>
        </inertia>
      </inertial>
      <pose frame=''>0.055 -0.095 0.03 -2.09427 1.57 9.2e-05</pose>
      <gravity>1</gravity><self_collide>0</self_collide>
      <kinematic>0</kinematic><enable_wind>0</enable_wind>
      <visual name='visual_0'>
        <geometry>
          <cylinder><radius>0.03</radius><length>0.015</length></cylinder>
        </geometry>
        <material>
          <ambient>0.3 0.3 0.3 1</ambient><diffuse>0.7 0.7 0.7 1</diffuse>
          <specular>0.01 0.01 0.01 1</specular><emissive>0 0 0 1</emissive>
        </material>
        <transparency>1</transparency>
      </visual>
      <collision name='collision'>
        <geometry>
          <cylinder><radius>0.03</radius><length>0.015</length></cylinder>
        </geometry>
      </collision>
    </link>

    <link name='link_1_0_clone_clone_0'>
      <inertial>
        <mass>1</mass>
        <inertia>
          <ixx>0.145833</ixx><ixy>0</ixy><ixz>0</ixz>
          <iyy>0.145833</iyy><iyz>0</iyz><izz>0.125</izz>
        </inertia>
      </inertial>
      <pose frame=''>-0.11 -0 0.03 7.9e-05 1.57 7.3e-05</pose>
      <gravity>1</gravity><self_collide>0</self_collide>
      <kinematic>0</kinematic><enable_wind>0</enable_wind>
      <visual name='visual_0'>
        <geometry>
          <cylinder><radius>0.03</radius><length>0.015</length></cylinder>
        </geometry>
        <material>
          <ambient>0.3 0.3 0.3 1</ambient><diffuse>0.7 0.7 0.7 1</diffuse>
          <specular>0.01 0.01 0.01 1</specular><emissive>0 0 0 1</emissive>
        </material>
        <transparency>1</transparency>
      </visual>
      <collision name='collision'>
        <geometry>
          <cylinder><radius>0.03</radius><length>0.015</length></cylinder>
        </geometry>
      </collision>
    </link>

    <joint name='link_1_JOINT_0' type='fixed'>
      <parent>link_1</parent><child>lidar</child>
    </joint>
    <joint name='link_1_JOINT_1' type='revolute'>
      <parent>link_1</parent><child>link_1_0_clone_clone_0</child>
      <axis><xyz>0 0 1</xyz>
        <limit><lower>-1.79769e+308</lower><upper>1.79769e+308</upper>
               <effort>-1</effort><velocity>-1</velocity></limit>
      </axis>
    </joint>
    <joint name='link_1_JOINT_2' type='revolute'>
      <parent>link_1</parent><child>link_1_0_clone</child>
      <axis><xyz>0 0 1</xyz>
        <limit><lower>-1.79769e+308</lower><upper>1.79769e+308</upper>
               <effort>-1</effort><velocity>-1</velocity></limit>
      </axis>
    </joint>
    <joint name='link_1_JOINT_3' type='revolute'>
      <parent>link_1</parent><child>link_1_0_clone_clone</child>
      <axis><xyz>0 0 1</xyz>
        <limit><lower>-1.79769e+308</lower><upper>1.79769e+308</upper>
               <effort>-1</effort><velocity>-1</velocity></limit>
      </axis>
    </joint>

    <static>0</static>
    <allow_auto_disable>1</allow_auto_disable>
    <plugin name='model_push' filename='libtriton_push.so'/>
  </model>
</sdf>